<?xml version="1.0" encoding="utf-8"?>
<!-- =================================================================================== -->
<!-- |    This document was autogenerated by xacro from my_robot_integration.urdf.xacro | -->
<!-- |    EDITING THIS FILE BY HAND IS NOT RECOMMENDED                                 | -->
<!-- =================================================================================== -->
<!-- Name your robot here -->
<robot name="vanda1robot">
  <link name="dummy_link">
	</link>
  <joint name="dummy_link_joint" type="fixed">
    <parent link="dummy_link"/>
    <child link="base_link"/>
  </joint>
  <transmission name="rear_joint_transmission">
    <type>transmission_interface/SimpleTransmission</type>
    <joint name="rear_joint">
      <hardwareInterface>hardware_interface/EffortJointInterface</hardwareInterface>
    </joint>
    <actuator name="rear_joint_motor">
      <mechanicalReduction>1</mechanicalReduction>
    </actuator>
  </transmission>
  <transmission name="axle_L_joint_transmission">
    <type>transmission_interface/SimpleTransmission</type>
    <joint name="axle_L_joint">
      <hardwareInterface>hardware_interface/EffortJointInterface</hardwareInterface>
    </joint>
    <actuator name="axle_L_joint_motor">
      <mechanicalReduction>1</mechanicalReduction>
    </actuator>
  </transmission>
  <transmission name="wheel_L_joint_transmission">
    <type>transmission_interface/SimpleTransmission</type>
    <joint name="wheel_L_joint">
      <hardwareInterface>hardware_interface/EffortJointInterface</hardwareInterface>
    </joint>
    <actuator name="wheel_L_joint_motor">
      <mechanicalReduction>1</mechanicalReduction>
    </actuator>
  </transmission>
  <transmission name="axle_R_joint_transmission">
    <type>transmission_interface/SimpleTransmission</type>
    <joint name="axle_R_joint">
      <hardwareInterface>hardware_interface/EffortJointInterface</hardwareInterface>
    </joint>
    <actuator name="axle_R_joint_motor">
      <mechanicalReduction>1</mechanicalReduction>
    </actuator>
  </transmission>
  <transmission name="wheel_R_joint_transmission">
    <type>transmission_interface/SimpleTransmission</type>
    <joint name="wheel_R_joint">
      <hardwareInterface>hardware_interface/EffortJointInterface</hardwareInterface>
    </joint>
    <actuator name="wheel_R_joint_motor">
      <mechanicalReduction>1</mechanicalReduction>
    </actuator>
  </transmission>
  <link name="base_link">
    <inertial>
      <origin rpy="0 0 0" xyz="-1.7202E-06 -0.026052 -0.016592"/>
      <mass value="7.3184"/>
      <inertia ixx="0.46741" ixy="-8.5881E-08" ixz="2.7588E-06" iyy="0.53589" iyz="0.0011101" izz="0.071662"/>
    </inertial>
    <visual>
      <origin rpy="0 0 0" xyz="0 0 0"/>
      <geometry>
        <mesh filename="package://vanda1/meshes/base_link.STL"/>
      </geometry>
      <material name="">
        <color rgba="1 1 1 1"/>
      </material>
    </visual>
    <collision>
      <origin rpy="0 0 0" xyz="0 0 0"/>
      <geometry>
        <mesh filename="package://vanda1/meshes/base_link.STL"/>
      </geometry>
    </collision>
  </link>
  <link name="axle_L_link">
    <inertial>
      <origin rpy="0 0 0" xyz="0.0051726 -0.048752 -5.1174E-10"/>
      <mass value="0.67643"/>
      <inertia ixx="0.00066353" ixy="7.4103E-05" ixz="1.5677E-11" iyy="0.00017491" iyz="1.4872E-13" izz="0.00076384"/>
    </inertial>
    <visual>
      <origin rpy="0 0 0" xyz="0 0 0"/>
      <geometry>
        <mesh filename="package://vanda1/meshes/axle_L_link.STL"/>
      </geometry>
      <material name="">
        <color rgba="0.52941 0.54902 0.54902 1"/>
      </material>
    </visual>
    <collision>
      <origin rpy="0 0 0" xyz="0 0 0"/>
      <geometry>
        <mesh filename="package://vanda1/meshes/axle_L_link.STL"/>
      </geometry>
    </collision>
  </link>
  <joint name="axle_L_joint" type="continuous">
    <origin rpy="1.5708 0 3.1416" xyz="-0.2286 0.254 0"/>
    <parent link="base_link"/>
    <child link="axle_L_link"/>
    <axis xyz="0 1 0"/>
  </joint>
  <link name="wheel_L_link">
    <inertial>
      <origin rpy="0 0 0" xyz="4.8047E-07 -6.4496E-08 -0.006751"/>
      <mass value="1.9945"/>
      <inertia ixx="0.010313" ixy="1.1778E-08" ixz="2.8825E-08" iyy="0.010313" iyz="-3.8693E-09" izz="0.018238"/>
    </inertial>
    <visual>
      <origin rpy="0 0 0" xyz="0 0 0"/>
      <geometry>
        <mesh filename="package://vanda1/meshes/wheel_L_link.STL"/>
      </geometry>
      <material name="">
        <color rgba="1 0.80784 0.49804 1"/>
      </material>
    </visual>
    <collision>
      <origin rpy="0 0 0" xyz="0 0 0"/>
      <geometry>
        <mesh filename="package://vanda1/meshes/wheel_L_link.STL"/>
      </geometry>
    </collision>
  </link>
  <joint name="wheel_L_joint" type="continuous">
    <origin rpy="1.5708 -0.3918 -1.5708" xyz="0 -0.0762 0"/>
    <parent link="axle_L_link"/>
    <child link="wheel_L_link"/>
    <axis xyz="0 0 1"/>
  </joint>
  <link name="axle_R_link">
    <inertial>
      <origin rpy="0 0 0" xyz="0.0051726 -0.048752 -5.1174E-10"/>
      <mass value="0.67643"/>
      <inertia ixx="0.00066353" ixy="7.4103E-05" ixz="1.5677E-11" iyy="0.00017491" iyz="1.4872E-13" izz="0.00076384"/>
    </inertial>
    <visual>
      <origin rpy="0 0 0" xyz="0 0 0"/>
      <geometry>
        <mesh filename="package://vanda1/meshes/axle_R_link.STL"/>
      </geometry>
      <material name="">
        <color rgba="0.52941 0.54902 0.54902 1"/>
      </material>
    </visual>
    <collision>
      <origin rpy="0 0 0" xyz="0 0 0"/>
      <geometry>
        <mesh filename="package://vanda1/meshes/axle_R_link.STL"/>
      </geometry>
    </collision>
  </link>
  <joint name="axle_R_joint" type="continuous">
    <origin rpy="1.5708 0 0" xyz="0.2286 0.254 0"/>
    <parent link="base_link"/>
    <child link="axle_R_link"/>
    <axis xyz="0 1 0"/>
  </joint>
  <link name="wheel_R_link">
    <inertial>
      <origin rpy="0 0 0" xyz="4.8047E-07 -6.4496E-08 -0.006751"/>
      <mass value="1.9945"/>
      <inertia ixx="0.010313" ixy="1.1778E-08" ixz="2.8825E-08" iyy="0.010313" iyz="-3.8693E-09" izz="0.018238"/>
    </inertial>
    <visual>
      <origin rpy="0 0 0" xyz="0 0 0"/>
      <geometry>
        <mesh filename="package://vanda1/meshes/wheel_R_link.STL"/>
      </geometry>
      <material name="">
        <color rgba="1 0.80784 0.49804 1"/>
      </material>
    </visual>
    <collision>
      <origin rpy="0 0 0" xyz="0 0 0"/>
      <geometry>
        <mesh filename="package://vanda1/meshes/wheel_R_link.STL"/>
      </geometry>
    </collision>
  </link>
  <joint name="wheel_R_joint" type="continuous">
    <origin rpy="1.5708 0.3918 -1.5708" xyz="0 -0.0762 0"/>
    <parent link="axle_R_link"/>
    <child link="wheel_R_link"/>
    <axis xyz="0 0 1"/>
  </joint>
  <link name="rear_link">
    <inertial>
      <origin rpy="0 0 0" xyz="-1.7202E-06 -0.026052 -0.016592"/>
      <mass value="7.3184"/>
      <inertia ixx="0.46741" ixy="-8.5881E-08" ixz="2.7588E-06" iyy="0.53589" iyz="0.0011101" izz="0.071662"/>
    </inertial>
    <visual>
      <origin rpy="0 0 0" xyz="0 0 0"/>
      <geometry>
        <mesh filename="package://vanda1/meshes/rear_link.STL"/>
      </geometry>
      <material name="">
        <color rgba="1 1 1 1"/>
      </material>
    </visual>
    <collision>
      <origin rpy="0 0 0" xyz="0 0 0"/>
      <geometry>
        <mesh filename="package://vanda1/meshes/rear_link.STL"/>
      </geometry>
    </collision>
  </link>
  <joint name="rear_joint" type="continuous">
    <origin rpy="1.5708 0 0" xyz="0 -0.254 -0.0762"/>
    <parent link="base_link"/>
    <child link="rear_link"/>
    <axis xyz="1 0 0"/>
  </joint>
  <link name="base_laser">
    <inertial>
      <origin rpy="0 0 0" xyz="-0.00029774 0.0066667 0.00013047"/>
      <mass value="0.15717"/>
      <inertia ixx="6.7885E-05" ixy="-1.3987E-07" ixz="-8.1554E-07" iyy="0.00013173" iyz="-9.0932E-08" izz="7.1972E-05"/>
    </inertial>
    <visual>
      <origin rpy="0 0 0" xyz="0 0 0"/>
      <geometry>
        <mesh filename="package://click_urdf/meshes/ydlidar.dae"/>
      </geometry>
      <material name="">
        <color rgba="0.64706 0.61961 0.58824 1"/>
      </material>
    </visual>
    <collision>
      <origin rpy="0 0 0" xyz="0 0 0"/>
      <geometry>
        <mesh filename="package://click_urdf/meshes/ydlidar.dae"/>
      </geometry>
    </collision>
  </link>
  <link name="laser_frame">
    <inertial>
      <origin rpy="0 0 0" xyz="-0.00036659 0.00064155 -0.00027052"/>
      <mass value="0.25482"/>
      <inertia ixx="8.9194E-05" ixy="1.8116E-07" ixz="3.6435E-08" iyy="0.00018279" iyz="2.423E-07" izz="0.00011103"/>
    </inertial>
    <!--visual>
      <origin
        xyz="0 0 0"
        rpy="0 0 0" />
      <geometry>
        <mesh
          filename="package://click_urdf/meshes/ydlidar.dae" />
      </geometry>
      <material
        name="">
        <color
          rgba="0.64706 0.61961 0.58824 1" />
      </material>
    </visual-->
    <!--collision>
      <origin
        xyz="0 0 0"
        rpy="0 0 0" />
      <geometry>
        <mesh
          filename="package://click_urdf/meshes/ydlidar.dae" />
      </geometry>
    </collision-->
  </link>
  <joint name="laser_joint" type="fixed">
    <origin rpy="0 0 0" xyz="0 0 0.03172"/>
    <parent link="base_laser"/>
    <child link="laser_frame"/>
    <axis xyz="0 0 0"/>
  </joint>
  <!-- Add your gazebo sensors here -->
  <!-- Add Lidar sensor caracteristics here -->
  <gazebo reference="base_laser">
    <!-- <gravity>true</gravity> -->
    <!-- Gazebo has fixed set of Sensors types. Check them out here <> -->
    <sensor name="laser" type="ray">
      <!-- Add in your sensor characteristics -->
      <pose> 0 0 0 0 0 0 </pose>
      <!-- <visualise>true</visualise> -->
      <update_rate>40</update_rate>
      <!-- <always_on>true</always_on> -->
      <ray>
        <scan>
          <horizontal>
            <samples>720</samples>
            <resolution>1</resolution>
            <min_angle>-1.570796</min_angle>
            <max_angle>1.570796</max_angle>
          </horizontal>
        </scan>
        <range>
          <min>0.10</min>
          <max>30.0</max>
          <resolution>0.01</resolution>
        </range>
        <noise>
          <type>gaussian</type>
          <mean>0.0</mean>
          <stddev>0.01</stddev>
        </noise>
      </ray>
      <plugin filename="libgazebo_ros_laser.so" name="gazebo_ros_head_hokuyo_controller">
        <!-- Use topic name as /my_robot/scan -->
        <topicName>/vanda1robot/scan</topicName>
        <frameName>laser_frame</frameName>
      </plugin>
    </sensor>
  </gazebo>
  <!-- Add gazebo plugin for control here -->
  <gazebo>
    <plugin filename="libgazebo_ros_control.so" name="gazebo_ros_control">
      <robotNamespace>/vanda1robot</robotNamespace>
    </plugin>
  </gazebo>
  <!-- Create a joint between your robot and sensor -->
  <!--   <joint
  	name="dummy_link_joint" type="fixed">
  	<parent link="dummy_link" />
  	<child link="base_link" />
  </joint> -->
  <joint name="sensor_joint" type="fixed">
    <origin rpy="0 0 0" xyz="0 0 0"/>
    <parent link="base_link"/>
    <child link="base_laser"/>
  </joint>
</robot>
